Traceback (most recent call last):
  File "/opt/homebrew/Caskroom/miniconda/base/envs/llm-env/lib/python3.11/site-packages/jupyter_cache/executors/utils.py", line 58, in single_nb_execution
    executenb(
  File "/opt/homebrew/Caskroom/miniconda/base/envs/llm-env/lib/python3.11/site-packages/nbclient/client.py", line 1305, in execute
    return NotebookClient(nb=nb, resources=resources, km=km, **kwargs).execute()
           ^^^^^^^^^^^^^^^^^^^^^^^^^^^^^^^^^^^^^^^^^^^^^^^^^^^^^^^^^^^^^^^^^^^^^
  File "/opt/homebrew/Caskroom/miniconda/base/envs/llm-env/lib/python3.11/site-packages/jupyter_core/utils/__init__.py", line 173, in wrapped
    return loop.run_until_complete(inner)
           ^^^^^^^^^^^^^^^^^^^^^^^^^^^^^^
  File "/opt/homebrew/Caskroom/miniconda/base/envs/llm-env/lib/python3.11/asyncio/base_events.py", line 653, in run_until_complete
    return future.result()
           ^^^^^^^^^^^^^^^
  File "/opt/homebrew/Caskroom/miniconda/base/envs/llm-env/lib/python3.11/site-packages/nbclient/client.py", line 705, in async_execute
    await self.async_execute_cell(
  File "/opt/homebrew/Caskroom/miniconda/base/envs/llm-env/lib/python3.11/site-packages/nbclient/client.py", line 1058, in async_execute_cell
    await self._check_raise_for_error(cell, cell_index, exec_reply)
  File "/opt/homebrew/Caskroom/miniconda/base/envs/llm-env/lib/python3.11/site-packages/nbclient/client.py", line 914, in _check_raise_for_error
    raise CellExecutionError.from_cell_and_msg(cell, exec_reply_content)
nbclient.exceptions.CellExecutionError: An error occurred while executing the following cell:
------------------
import json
from openai import OpenAI
import os
from dotenv import load_dotenv

load_dotenv()
client = OpenAI()
------------------


[0;31m---------------------------------------------------------------------------[0m
[0;31mOpenAIError[0m                               Traceback (most recent call last)
Cell [0;32mIn[1], line 7[0m
[1;32m      4[0m [38;5;28;01mfrom[39;00m [38;5;21;01mdotenv[39;00m [38;5;28;01mimport[39;00m load_dotenv
[1;32m      6[0m load_dotenv()
[0;32m----> 7[0m client [38;5;241m=[39m [43mOpenAI[49m[43m([49m[43m)[49m

File [0;32m/opt/homebrew/Caskroom/miniconda/base/envs/llm-env/lib/python3.11/site-packages/openai/_client.py:93[0m, in [0;36mOpenAI.__init__[0;34m(self, api_key, organization, base_url, timeout, max_retries, default_headers, default_query, http_client, _strict_response_validation)[0m
[1;32m     91[0m     api_key [38;5;241m=[39m os[38;5;241m.[39menviron[38;5;241m.[39mget([38;5;124m"[39m[38;5;124mOPENAI_API_KEY[39m[38;5;124m"[39m)
[1;32m     92[0m [38;5;28;01mif[39;00m api_key [38;5;129;01mis[39;00m [38;5;28;01mNone[39;00m:
[0;32m---> 93[0m     [38;5;28;01mraise[39;00m OpenAIError(
[1;32m     94[0m         [38;5;124m"[39m[38;5;124mThe api_key client option must be set either by passing api_key to the client or by setting the OPENAI_API_KEY environment variable[39m[38;5;124m"[39m
[1;32m     95[0m     )
[1;32m     96[0m [38;5;28mself[39m[38;5;241m.[39mapi_key [38;5;241m=[39m api_key
[1;32m     98[0m [38;5;28;01mif[39;00m organization [38;5;129;01mis[39;00m [38;5;28;01mNone[39;00m:

[0;31mOpenAIError[0m: The api_key client option must be set either by passing api_key to the client or by setting the OPENAI_API_KEY environment variable

