Traceback (most recent call last):
  File "/Users/peilinliao/Library/CloudStorage/OneDrive-NorthwesternUniversity/Documents/pythonenv/jupyterbook/lib/python3.12/site-packages/jupyter_cache/executors/utils.py", line 58, in single_nb_execution
    executenb(
  File "/Users/peilinliao/Library/CloudStorage/OneDrive-NorthwesternUniversity/Documents/pythonenv/jupyterbook/lib/python3.12/site-packages/nbclient/client.py", line 1305, in execute
    return NotebookClient(nb=nb, resources=resources, km=km, **kwargs).execute()
           ^^^^^^^^^^^^^^^^^^^^^^^^^^^^^^^^^^^^^^^^^^^^^^^^^^^^^^^^^^^^^^^^^^^^^
  File "/Users/peilinliao/Library/CloudStorage/OneDrive-NorthwesternUniversity/Documents/pythonenv/jupyterbook/lib/python3.12/site-packages/jupyter_core/utils/__init__.py", line 173, in wrapped
    return loop.run_until_complete(inner)
           ^^^^^^^^^^^^^^^^^^^^^^^^^^^^^^
  File "/Users/peilinliao/Library/CloudStorage/OneDrive-NorthwesternUniversity/Documents/pythonenv/jupyterbook/lib/python3.12/asyncio/base_events.py", line 664, in run_until_complete
    return future.result()
           ^^^^^^^^^^^^^^^
  File "/Users/peilinliao/Library/CloudStorage/OneDrive-NorthwesternUniversity/Documents/pythonenv/jupyterbook/lib/python3.12/site-packages/nbclient/client.py", line 705, in async_execute
    await self.async_execute_cell(
  File "/Users/peilinliao/Library/CloudStorage/OneDrive-NorthwesternUniversity/Documents/pythonenv/jupyterbook/lib/python3.12/site-packages/nbclient/client.py", line 1058, in async_execute_cell
    await self._check_raise_for_error(cell, cell_index, exec_reply)
  File "/Users/peilinliao/Library/CloudStorage/OneDrive-NorthwesternUniversity/Documents/pythonenv/jupyterbook/lib/python3.12/site-packages/nbclient/client.py", line 914, in _check_raise_for_error
    raise CellExecutionError.from_cell_and_msg(cell, exec_reply_content)
nbclient.exceptions.CellExecutionError: An error occurred while executing the following cell:
------------------
import json
import openai
import os
import pandas as pd
from pprint import pprint

# api_file ="__api_file_path__"
with open(api_file, 'r') as f:
    openai.api_key = f.read().strip()
------------------


[0;31m---------------------------------------------------------------------------[0m
[0;31mModuleNotFoundError[0m                       Traceback (most recent call last)
Cell [0;32mIn[1], line 2[0m
[1;32m      1[0m [38;5;28;01mimport[39;00m [38;5;21;01mjson[39;00m
[0;32m----> 2[0m [38;5;28;01mimport[39;00m [38;5;21;01mopenai[39;00m
[1;32m      3[0m [38;5;28;01mimport[39;00m [38;5;21;01mos[39;00m
[1;32m      4[0m [38;5;28;01mimport[39;00m [38;5;21;01mpandas[39;00m [38;5;28;01mas[39;00m [38;5;21;01mpd[39;00m

[0;31mModuleNotFoundError[0m: No module named 'openai'

