Traceback (most recent call last):
  File "/kellogg/software/miniconda3-python311/envs/llm-env/lib/python3.11/site-packages/jupyter_cache/executors/utils.py", line 58, in single_nb_execution
    executenb(
  File "/kellogg/software/miniconda3-python311/envs/llm-env/lib/python3.11/site-packages/nbclient/client.py", line 1305, in execute
    return NotebookClient(nb=nb, resources=resources, km=km, **kwargs).execute()
           ^^^^^^^^^^^^^^^^^^^^^^^^^^^^^^^^^^^^^^^^^^^^^^^^^^^^^^^^^^^^^^^^^^^^^
  File "/kellogg/software/miniconda3-python311/envs/llm-env/lib/python3.11/site-packages/jupyter_core/utils/__init__.py", line 173, in wrapped
    return loop.run_until_complete(inner)
           ^^^^^^^^^^^^^^^^^^^^^^^^^^^^^^
  File "/kellogg/software/miniconda3-python311/envs/llm-env/lib/python3.11/asyncio/base_events.py", line 653, in run_until_complete
    return future.result()
           ^^^^^^^^^^^^^^^
  File "/kellogg/software/miniconda3-python311/envs/llm-env/lib/python3.11/site-packages/nbclient/client.py", line 705, in async_execute
    await self.async_execute_cell(
  File "/kellogg/software/miniconda3-python311/envs/llm-env/lib/python3.11/site-packages/nbclient/client.py", line 1058, in async_execute_cell
    await self._check_raise_for_error(cell, cell_index, exec_reply)
  File "/kellogg/software/miniconda3-python311/envs/llm-env/lib/python3.11/site-packages/nbclient/client.py", line 914, in _check_raise_for_error
    raise CellExecutionError.from_cell_and_msg(cell, exec_reply_content)
nbclient.exceptions.CellExecutionError: An error occurred while executing the following cell:
------------------
import json
import openai
import os
import pandas as pd
from pprint import pprint

# api_file ="__api_file_path__"
with open(api_file, 'r') as f:
    openai.api_key = f.read().strip()
------------------


[0;31m---------------------------------------------------------------------------[0m
[0;31mNameError[0m                                 Traceback (most recent call last)
Cell [0;32mIn[1], line 8[0m
[1;32m      5[0m [38;5;28;01mfrom[39;00m [38;5;21;01mpprint[39;00m [38;5;28;01mimport[39;00m pprint
[1;32m      7[0m [38;5;66;03m# api_file ="__api_file_path__"[39;00m
[0;32m----> 8[0m [38;5;28;01mwith[39;00m [38;5;28mopen[39m([43mapi_file[49m, [38;5;124m'[39m[38;5;124mr[39m[38;5;124m'[39m) [38;5;28;01mas[39;00m f:
[1;32m      9[0m     openai[38;5;241m.[39mapi_key [38;5;241m=[39m f[38;5;241m.[39mread()[38;5;241m.[39mstrip()

[0;31mNameError[0m: name 'api_file' is not defined

